2017-04-26 21:12:55,654 [Thread-12:8948] [django.request:256] [base:handle_uncaught_exception] [ERROR]- Internal Server Error: /admin/home/question/
Traceback (most recent call last):
  File "F:\DjangoSpace\Graduate\QandA-env\lib\site-packages\django\core\handlers\base.py", line 132, in get_response
    response = wrapped_callback(request, *callback_args, **callback_kwargs)
  File "F:\DjangoSpace\Graduate\QandA-env\lib\site-packages\django\contrib\admin\options.py", line 618, in wrapper
    return self.admin_site.admin_view(view)(*args, **kwargs)
  File "F:\DjangoSpace\Graduate\QandA-env\lib\site-packages\django\utils\decorators.py", line 110, in _wrapped_view
    response = view_func(request, *args, **kwargs)
  File "F:\DjangoSpace\Graduate\QandA-env\lib\site-packages\django\views\decorators\cache.py", line 57, in _wrapped_view_func
    response = view_func(request, *args, **kwargs)
  File "F:\DjangoSpace\Graduate\QandA-env\lib\site-packages\django\contrib\admin\sites.py", line 233, in inner
    return view(request, *args, **kwargs)
  File "F:\DjangoSpace\Graduate\QandA-env\lib\site-packages\django\utils\decorators.py", line 34, in _wrapper
    return bound_func(*args, **kwargs)
  File "F:\DjangoSpace\Graduate\QandA-env\lib\site-packages\django\utils\decorators.py", line 110, in _wrapped_view
    response = view_func(request, *args, **kwargs)
  File "F:\DjangoSpace\Graduate\QandA-env\lib\site-packages\django\utils\decorators.py", line 30, in bound_func
    return func.__get__(self, type(self))(*args2, **kwargs2)
  File "F:\DjangoSpace\Graduate\QandA-env\lib\site-packages\django\contrib\admin\options.py", line 1550, in changelist_view
    self.list_max_show_all, self.list_editable, self)
  File "F:\DjangoSpace\Graduate\QandA-env\lib\site-packages\django\contrib\admin\views\main.py", line 82, in __init__
    self.get_results(request)
  File "F:\DjangoSpace\Graduate\QandA-env\lib\site-packages\django\contrib\admin\views\main.py", line 177, in get_results
    result_count = paginator.count
  File "F:\DjangoSpace\Graduate\QandA-env\lib\site-packages\django\core\paginator.py", line 72, in _get_count
    self._count = self.object_list.count()
  File "F:\DjangoSpace\Graduate\QandA-env\lib\site-packages\django\db\models\query.py", line 318, in count
    return self.query.get_count(using=self.db)
  File "F:\DjangoSpace\Graduate\QandA-env\lib\site-packages\django\db\models\sql\query.py", line 466, in get_count
    number = obj.get_aggregation(using, ['__count'])['__count']
  File "F:\DjangoSpace\Graduate\QandA-env\lib\site-packages\django\db\models\sql\query.py", line 447, in get_aggregation
    result = compiler.execute_sql(SINGLE)
  File "F:\DjangoSpace\Graduate\QandA-env\lib\site-packages\django\db\models\sql\compiler.py", line 840, in execute_sql
    cursor.execute(sql, params)
  File "F:\DjangoSpace\Graduate\QandA-env\lib\site-packages\django\db\backends\utils.py", line 79, in execute
    return super(CursorDebugWrapper, self).execute(sql, params)
  File "F:\DjangoSpace\Graduate\QandA-env\lib\site-packages\django\db\backends\utils.py", line 64, in execute
    return self.cursor.execute(sql, params)
  File "F:\DjangoSpace\Graduate\QandA-env\lib\site-packages\django\db\utils.py", line 98, in __exit__
    six.reraise(dj_exc_type, dj_exc_value, traceback)
  File "F:\DjangoSpace\Graduate\QandA-env\lib\site-packages\django\db\backends\utils.py", line 64, in execute
    return self.cursor.execute(sql, params)
  File "F:\DjangoSpace\Graduate\QandA-env\lib\site-packages\django\db\backends\sqlite3\base.py", line 318, in execute
    return Database.Cursor.execute(self, query, params)
OperationalError: no such table: home_question
2017-04-26 22:49:09,984 [Thread-32:6488] [django.request:256] [base:handle_uncaught_exception] [ERROR]- Internal Server Error: /inbox/
Traceback (most recent call last):
  File "F:\DjangoSpace\Graduate\QandA-env\lib\site-packages\django\core\handlers\base.py", line 132, in get_response
    response = wrapped_callback(request, *callback_args, **callback_kwargs)
  File "F:\DjangoSpace\Graduate\QandA\home\views.py", line 87, in inbox
    message_list=Message.objects.filter(user_id=client.id)
AttributeError: 'NoneType' object has no attribute 'id'
2017-04-26 22:49:10,096 [Thread-33:8988] [django.request:256] [base:handle_uncaught_exception] [ERROR]- Internal Server Error: /logout
Traceback (most recent call last):
  File "F:\DjangoSpace\Graduate\QandA-env\lib\site-packages\django\core\handlers\base.py", line 132, in get_response
    response = wrapped_callback(request, *callback_args, **callback_kwargs)
  File "F:\DjangoSpace\Graduate\QandA-env\lib\site-packages\django\views\decorators\csrf.py", line 58, in wrapped_view
    return view_func(*args, **kwargs)
  File "F:\DjangoSpace\Graduate\QandA\home\views.py", line 69, in logout
    print client.mobile, 'logout'
AttributeError: 'NoneType' object has no attribute 'mobile'
2017-04-26 22:49:21,747 [Thread-35:8240] [django.request:170] [base:get_response] [WARNING]- Not Found: /favicon.ico
